Exception in thread Thread-1 (_get_log):
Traceback (most recent call last):
  File "/usr/local/Cellar/python@3.12/3.12.8/Frameworks/Python.framework/Versions/3.12/lib/python3.12/threading.py", line 1075, in _bootstrap_inner
    self.run()
  File "/usr/local/Cellar/python@3.12/3.12.8/Frameworks/Python.framework/Versions/3.12/lib/python3.12/threading.py", line 1012, in run
    self._target(*self._args, **self._kwargs)
  File "/usr/local/Cellar/azure-cli/2.68.0/libexec/lib/python3.12/site-packages/azure/cli/command_modules/appservice/custom.py", line 3508, in _get_log
    raise CLIError("Failed to connect to '{}' with status code '{}' and reason '{}'".format(
knack.util.CLIError: Failed to connect to 'https://azurephotoflowwebapp.scm.azurewebsites.net/logstream' with status code '503' and reason 'Service Unavailable'
